<?xml version="1.0" encoding="utf-8"?>
<!-- This URDF was automatically created by SolidWorks to URDF Exporter! Originally created by Stephen Brawner (brawner@gmail.com) 
     Commit Version: 1.6.0-4-g7f85cfe  Build Version: 1.6.7995.38578
     For more information, please see http://wiki.ros.org/sw_urdf_exporter -->
<robot  name="RoboBall_URDF" xml:drake="https://drake.mit.edu">
  <link  name="pitch_center">
    <inertial>
      <origin
        xyz="0 0 -0.05 "
        rpy="0 0 0" />
      <mass
        value="2.77934" />
      <inertia
        ixx="0.01841"
        iyy="0.00754"
        izz="0.01442" 
        ixy = "0.0"
        iyz = "0.0"
        izy = "0.0"/>
    </inertial>
    <visual>
      <origin
        xyz="0 0 0"
        rpy="-1.57 0 0" />
      <geometry>
        <box size="0.15 0.1 0.15"/>
      </geometry>
      <material
        name="">
        <color
          rgba="1 1 1 1" />
      </material>
    </visual>
  </link>
  <link  name="pendulum">
    <inertial>
      <origin
        xyz="0  0.0033714 -0.095"
        rpy="0 0 0" />
      <mass
        value="22.03" />
      <inertia
        ixx="0.44235"
        iyy="0.49888"
        izz="0.32633"
        ixy = "0.0"
        iyz = "0.0"
        izy = "0.0"  />
    </inertial>
    <visual>
      <origin
        xyz="0 0 -0.15"
        rpy="-1.57 0 0" />
      <geometry>
        <box size="0.15 0.2 0.15"/>
      </geometry>
      <material
        name="">
        <color
          rgba="1 0.647058823529412 0.125490196078431 1" />
      </material>
    </visual>
  </link>
  <joint name="steer"
    type="revolute">
    <origin
      xyz="0 0 0"
      rpy="0 0 0" />
    <parent
      link="pitch_center" />
    <child
      link="pendulum" />
    <axis
      xyz="1 0 0" />
    <limit
      lower="-1.57"
      upper="1.0" />
  </joint>
  <link name="pipe_assembly">
    <inertial>
      <origin
        xyz="0 0 0"
        rpy="0 0 0" />
      <mass
        value="16.53649" />
      <inertia
        ixx="1.04"
        iyy="0.64074"
        izz="1.04" 
        ixy = "0.0"
        iyz = "0.0"
        izy = "0.0"/>
    </inertial>
    <visual>
      <origin
        xyz="0 0 0"
        rpy="-1.57 0 1.57" />
      <geometry>
        <mesh
          filename="package://RoboBall_URDF/meshes/pipe_assembly.obj" />
      </geometry>
      <material
        name="">
        <color
          rgba="1 0.647058823529412 0.125490196078431 1" />
      </material>
    </visual>
    <collision>
      <origin
        xyz="0 0 0"
        rpy="-1.57 0 1.57" />
      <geometry>
        <mesh
          filename="package://RoboBall_URDF/meshes/pipe_assembly.obj" />
      </geometry>
    </collision>
  </link>
  <joint  name="drive"
    type="continuous">
    <origin
      xyz="0 0 0"
      rpy="0 0 0" />
    <parent
      link="pitch_center" />
    <child
      link="pipe_assembly" />
    <axis
      xyz="0 -1 0" />
  </joint>
  <link  name="bedliner">
    <visual>
      <origin
        xyz="0 0 0"
        rpy="-1.57 0 1.57" />
      <geometry>
        <mesh
          filename="package://RoboBall_URDF/meshes/bedliner_lumpy.obj" />
      </geometry>
      <material
        name="">
        <color
          rgba="1 1 1 0.24" />
      </material>
    </visual>
    <collision name="bed_collision">
      <origin
        xyz="0 0 0"
        rpy="0 0 0" />
      <geometry>
        <sphere 
            radius = "0.305"/>
      </geometry>
      <drake:proximity_properties>
      <drake:compliant_hydroelastic/>
      <drake:mesh_resolution_hint value="0.1"/>
      <drake:hydroelastic_modulus value="1.8e6"/> 
      <drake:hunt_crossley_dissipation value="0.5"/>
    </drake:proximity_properties> 
    </collision>
  </link>
  <joint   name="beadlocked"
    type="fixed">
    <origin
      xyz="0 0 0"
      rpy="0 0 0" />
    <parent
      link="pipe_assembly" />
    <child
      link="bedliner" />
    <axis
      xyz="0 0 0" />
  </joint>
  <transmission type="SimpleTransmission" name="drive_motor">
    <actuator name="drive"/>
    <joint name="drive"/>
    <mechanicalReduction>1</mechanicalReduction>
  </transmission>

  <transmission type="SimpleTransmission" name="steer_motor">
      <actuator name="steer"/>
      <joint name="steer"/>
      <mechanicalReduction>1</mechanicalReduction>
    </transmission>
</robot>